Workbook

Sheet Inputs
A1: Cozumel group budget — inputs (blue cells are editable)
A2: item | B2: value | C2: unit | D2: flag / source
A3: Pricing basis
A4: Pricing headcount: people including George at which the fee is set (larger groups make a surplus) | B4: 30 | C4: people | D4: policy (George, 28 Sep): 30, last year was 40
A5: Minimum headcount the contingency must cover | B5: 14 | C5: people | D5: policy (George, 28 Sep): fee 1,350 / 1,200 is covered from 14 (13 loses the odd-room cost)
A6: Share of participants who are Open Water students | B6: 0.5 | C6: share | D6: brief
A7: Contingency inside the fee (refunded pro rata if unused) | B7: 0.03 | C7: share | D7: policy (George, 28 Sep): 3%, rounding to 50 adds the rest
A8: Blue Note Scuba (QUOTED 23 Sep 2026, Doug Atkinson)
A9: Open Water course, 3 days, equipment included | B9: 400 | C9: USD | D9: QUOTED
A10: Two extra boat days for new divers (Thu–Fri) | B10: 240 | C10: USD | D10: QUOTED
A11: Certified 5-day two-tank package | B11: 600 | C11: USD | D11: QUOTED
A12: Equipment rental per day, everyone rents (in the fee) | B12: 30 | C12: USD/day | D12: QUOTED 24 Sep: full set BCD, regulator, mask, fins, wetsuit; bulk-rate ask saved for October
A13: Dive computer rental per day (included on courses; extra on regular rentals) | B13: 10 | C13: USD/day | D13: QUOTED 24 Sep; in the fee for every boat day under the everyone-rents rule
A14: Rental days, certified | B14: 5 | C14: days | D14: programme
A15: Rental days, new divers (course includes equipment; the two extra boat days do not) | B15: 2 | C15: days | D15: ASSUMED; ask Blue Note whether the USD 240 extra days include gear
A16: Marine park fee per boat day | B16: 13 | C16: USD/day | D16: ADVERTISED: 225 pesos in 2026 (Blue Note site shows USD 12 / 220 pesos); QUOTED 23 Sep: paid on site for boat days only, none on the two training-site days
A17: Boat days, certified | B17: 5 | C17: days | D17: programme
A18: Boat days, new divers (dive 3–4 day + Thu + Fri) | B18: 3 | C18: days | D18: programme
A19: Commission on certified packages, paid to George | B19: 0.1 | C19: share | D19: QUOTED: deducted from the invoice
A20: One free certified package per N paid | B20: 5 | C20: paid | D20: QUOTED
... A25: Nitrox fill per tank (course free with eLearning) | B25: 12 | C25: USD | D25: INFERRED; QUOTE NEEDED
A26: Hotel Plaza Cozumel (QUOTED via Blue Note's contracted rate)
A27: Room per night, 2 people with breakfast, low-rate nights | B27: 70 | C27: USD | D27: QUOTED (Dec 14–15 rate)
A28: Room per night, 2 people with breakfast, high-rate nights | B28: 88 | C28: USD | D28: QUOTED (Dec 16–19 rate)
A29: Low-rate nights (Sun 13, Mon 14) | B29: 2 | C29: nights | D29: assumes the Dec 14–15 rate covers the nights of 13 and 14; CONFIRM
A30: High-rate nights (Tue 15 – Fri 18) | B30: 4 | C30: nights
A31: Hotel deposit at booking (share of block) | B31: 0.25 | C31: share | D31: QUOTE NEEDED; assumption
A32: Hotel Plaza: one complimentary room per N paid rooms | B32: 14 | C32: rooms | D32: QUOTED 25 Sep via Blue Note (20 rooms blocked)
A33: Included in the fee for everyone
A34: PADI Open Water eLearning (club buys the codes) | B34: 230 | C34: USD | D34: ADVERTISED store.padi.com about USD 230; Blue Note asked for its code price
A35: Dive-accident cover inside the fee | B35: 0 | C35: USD | D35: QUOTED 25 Sep: DAN no longer lets shops buy cover for divers; each person buys their own (own spending below); OW students covered by the shop during the course only
A36: Tax buffer per head | B36: 0 | C36: USD | D36: QUOTED 24 Sep: Blue Note prices include taxes
A37: Leader costs carried by the group (George shares a room like everyone)
A38: George's flight allowance | B38: 700 | C38: USD | D38: policy; PHL–CZM band 568–800
A39: George's half of a shared room, 6 nights | B39: =(Inputs!$B$27*Inputs!$B$29+Inputs!$B$28*Inputs!$B$30)/2 -> 246 | C39: USD | D39: formula
A40: Odd-headcount room risk (one person alone at the group's cost) | B40: =Inputs!$B$39 -> 246 | C40: USD | D40: formula: half a room
A41: George's dive cover carried by the group | B41: 0 | C41: USD | D41: own cost like everyone (25 Sep)
A42: George's gear and computer rental, 5 days | B42: =(Inputs!$B$12+Inputs!$B$13)*5 -> 200 | C42: USD | D42: formula
A43: Own spending guidance, not in the fee (no flights)
A44: Lunches, dinners and drinks per day (breakfast included) | B44: 45 | C44: USD/day | D44: INFERRED for an MBA crowd
...

Sheet Fee
A1: Trip fee per person, set at the pricing headcount (USD, 2 sharing)
B2: Open Water student | C2: Certified diver
A3: Diving with Blue Note | B3: =Inputs!$B$9+Inputs!$B$10 -> 640 | C3: =Inputs!$B$11 -> 600
A4: Gear rental incl. computer, everyone | B4: =(Inputs!$B$12+Inputs!$B$13)*Inputs!$B$15 -> 80 | C4: =(Inputs!$B$12+Inputs!$B$13)*Inputs!$B$14 -> 200
A5: Marine park fees | B5: =Inputs!$B$16*Inputs!$B$18 -> 39 | C5: =Inputs!$B$16*Inputs!$B$17 -> 65
A6: Tax buffer (zero: Blue Note prices include taxes) | B6: =Inputs!$B$36 -> 0 | C6: =Inputs!$B$36 -> 0
A7: PADI eLearning | B7: =Inputs!$B$34 -> 230 | C7: 0
A8: Dive-accident cover (not in the fee: each person buys their own, see below) | B8: =Inputs!$B$35 -> 0 | C8: =Inputs!$B$35 -> 0
A9: Hotel Plaza, 6 nights with breakfast, 2 sharing | B9: =((Inputs!$B$27*Inputs!$B$29+Inputs!$B$28*Inputs!$B$30)/2) -> 246 | C9: =((Inputs!$B$27*Inputs!$B$29+Inputs!$B$28*Inputs!$B$30)/2) -> 246
A10: Leader's costs shared (George's flight, half-room, DAN, rental, odd-room risk) | B10: =(Inputs!$B$38+Inputs!$B$39+Inputs!$B$40+Inputs!$B$41+Inputs!$B$42)/(Inputs!$B$4-1) -> 48 | C10: =(Inputs!$B$38+Inputs!$B$39+Inputs!$B$40+Inputs!$B$41+Inputs!$B$42)/(Inputs!$B$4-1) -> 48
A11: Subtotal | B11: =SUM(B3:B10) -> 1283 | C11: =SUM(C3:C10) -> 1159
A12: Contingency | B12: =ROUND(B11*Inputs!$B$7,0) -> 38 | C12: =ROUND(C11*Inputs!$B$7,0) -> 35
A13: TRIP FEE (rounded up to the nearest 50, as posted) | B13: =CEILING(B11+B12,50) -> 1350 | C13: =CEILING(C11+C12,50) -> 1200
A15: Optional add-ons at sign-up, charged at cost
A16: AOW: course free with eLearning; eLearning | B16: n/a | C16: =Inputs!$B$49 -> 220
A17: Nitrox: course free with eLearning; 10 fills | B17: n/a | C17: =Inputs!$B$25*10 -> 120
A18: Afternoon two-tank dive, each, incl. park fee | B18: =Inputs!$B$22+Inputs!$B$16 -> 143 | C18: =Inputs!$B$22+Inputs!$B$16 -> 143
A19: Night dive, private charter shared by 10 | B19: =Inputs!$B$23/10 -> 80 | C19: =Inputs!$B$23/10 -> 80
A20: Shore dive on a free morning, incl. gear | B20: =Inputs!$B$24 -> 60 | C20: =Inputs!$B$24 -> 60
A22: GUIDANCE BUDGET WITHOUT FLIGHTS
A23: Trip fee | B23: =B13 -> 1350 | C23: =C13 -> 1200
A24: Own spending: DAN cover, meals, drinks, tips, airport transfers | B24: =Inputs!$B$48+Inputs!$B$44*Inputs!$B$45+Inputs!$B$46+Inputs!$B$47 -> 434 | C24: =Inputs!$B$48+Inputs!$B$44*Inputs!$B$45+Inputs!$B$46+Inputs!$B$47 -> 434
A25: Guidance budget | B25: =B23+B24 -> 1784 | C25: =C23+C24 -> 1634
A26: Guidance budget, certified taking AOW and nitrox | B26: n/a | C26: =C25+C16+C17 -> 1974
A28: The fee covers everything diving-related (course or package, gear and computer, park fees, eLearning) and the hotel; flights, the required DAN cover (bought by each person), meals, drinks, tips and transfers are the person's own. It is set at the pricing headcount; a bigger group makes a surplus that is refunded pro rata or held as buffer, a smaller group down to the minimum is covered by the contingency (see Group sheet). George's place: diving covered by Blue Note's comp, flight and room carried by the group, commission to George, all disclosed on the sign-up page.

Sheet Group
A1: Group budget at four sizes (half students; George leads and does not pay)
B2: 14 people (minimum) | C2: 20 people | D2: 30 people (pricing basis) | E2: 40 people
A3: People including George | B3: 14 | C3: 20 | D3: 30 | E3: 40
A4: Paying participants | B4: =B3-1 -> 13 | C4: =C3-1 -> 19 | D4: =D3-1 -> 29 | E4: =E3-1 -> 39
A5: Open Water students | B5: =ROUND(B4*Inputs!$B$6,0) -> 7 | C5: =ROUND(C4*Inputs!$B$6,0) -> 10 | D5: =ROUND(D4*Inputs!$B$6,0) -> 15 | E5: =ROUND(E4*Inputs!$B$6,0) -> 20
A6: Paying certified divers | B6: =B4-B5 -> 6 | C6: =C4-C5 -> 9 | D6: =D4-D5 -> 14 | E6: =E4-E5 -> 19
A7: Rooms, everyone 2 sharing including George (odd person alone at the group's cost) | B7: =ROUNDUP(B3/2,0) -> 7 | C7: =ROUNDUP(C3/2,0) -> 10 | D7: =ROUNDUP(D3/2,0) -> 15 | E7: =ROUNDUP(E3/2,0) -> 20
A8: Revenue
A9: Trip fees collected | B9: =B5*Fee!$B$13+B6*Fee!$C$13 -> 16650 | C9: =C5*Fee!$B$13+C6*Fee!$C$13 -> 24300 | D9: =D5*Fee!$B$13+D6*Fee!$C$13 -> 37050 | E9: =E5*Fee!$B$13+E6*Fee!$C$13 -> 49800
A10: Costs
A11: Blue Note: Open Water courses and extra days | B11: =B5*(Inputs!$B$9+Inputs!$B$10) -> 4480 | C11: =C5*(Inputs!$B$9+Inputs!$B$10) -> 6400 | D11: =D5*(Inputs!$B$9+Inputs!$B$10) -> 9600 | E11: =E5*(Inputs!$B$9+Inputs!$B$10) -> 12800
A12: Blue Note: certified packages, paid divers | B12: =B6*Inputs!$B$11 -> 3600 | C12: =C6*Inputs!$B$11 -> 5400 | D12: =D6*Inputs!$B$11 -> 8400 | E12: =E6*Inputs!$B$11 -> 11400
A13: Comps earned (1 per N paid certified) | B13: =INT(B6/Inputs!$B$20) -> 1 | C13: =INT(C6/Inputs!$B$20) -> 1 | D13: =INT(D6/Inputs!$B$20) -> 2 | E13: =INT(E6/Inputs!$B$20) -> 3
A14: George's package (free if at least one comp) | B14: =IF(B13>=1,0,Inputs!$B$11) -> 0 | C14: =IF(C13>=1,0,Inputs!$B$11) -> 0 | D14: =IF(D13>=1,0,Inputs!$B$11) -> 0 | E14: =IF(E13>=1,0,Inputs!$B$11) -> 0
A15: Spare comps credited against the invoice | B15: =-MAX(B13-1,0)*Inputs!$B$11 -> 0 | C15: =-MAX(C13-1,0)*Inputs!$B$11 -> 0 | D15: =-MAX(D13-1,0)*Inputs!$B$11 -> -600 | E15: =-MAX(E13-1,0)*Inputs!$B$11 -> -1200
A16: Blue Note gross invoice | B16: =B11+B12+B14+B15 -> 8080 | C16: =C11+C12+C14+C15 -> 11800 | D16: =D11+D12+D14+D15 -> 17400 | E16: =E11+E12+E14+E15 -> 23000
A17: Less 10% commission on paid certified packages | B17: =-B12*Inputs!$B$19 -> -360 | C17: =-C12*Inputs!$B$19 -> -540 | D17: =-D12*Inputs!$B$19 -> -840 | E17: =-E12*Inputs!$B$19 -> -1140
A18: Blue Note net payable | B18: =B16+B17 -> 7720 | C18: =C16+C17 -> 11260 | D18: =D16+D17 -> 16560 | E18: =E16+E17 -> 21860
A19: Commission passed to George | B19: =-B17 -> 360 | C19: =-C17 -> 540 | D19: =-D17 -> 840 | E19: =-E17 -> 1140
A20: Gear and computer rental for everyone including George | B20: =B5*(Inputs!$B$12+Inputs!$B$13)*Inputs!$B$15+(B6+1)*(Inputs!$B$12+Inputs!$B$13)*Inputs!$B$14 -> 1960 | C20: =C5*(Inputs!$B$12+Inputs!$B$13)*Inputs!$B$15+(C6+1)*(Inputs!$B$12+Inputs!$B$13)*Inputs!$B$14 -> 2800 | D20: =D5*(Inputs!$B$12+Inputs!$B$13)*Inputs!$B$15+(D6+1)*(Inputs!$B$12+Inputs!$B$13)*Inputs!$B$14 -> 4200 | E20: =E5*(Inputs!$B$12+Inputs!$B$13)*Inputs!$B$15+(E6+1)*(Inputs!$B$12+Inputs!$B$13)*Inputs!$B$14 -> 5600
A21: Tax buffer held (paid to Blue Note and the hotel if charged; otherwise refunded) | B21: =B3*Inputs!$B$36 -> 0 | C21: =C3*Inputs!$B$36 -> 0 | D21: =D3*Inputs!$B$36 -> 0 | E21: =E3*Inputs!$B$36 -> 0
A22: Marine park fees (cash on the island, paid from the float) | B22: =B5*Inputs!$B$16*Inputs!$B$18+(B6+1)*Inputs!$B$16*Inputs!$B$17 -> 728 | C22: =C5*Inputs!$B$16*Inputs!$B$18+(C6+1)*Inputs!$B$16*Inputs!$B$17 -> 1040 | D22: =D5*Inputs!$B$16*Inputs!$B$18+(D6+1)*Inputs!$B$16*Inputs!$B$17 -> 1560 | E22: =E5*Inputs!$B$16*Inputs!$B$18+(E6+1)*Inputs!$B$16*Inputs!$B$17 -> 2080
A23: PADI Open Water eLearning codes | B23: =B5*Inputs!$B$34 -> 1610 | C23: =C5*Inputs!$B$34 -> 2300 | D23: =D5*Inputs!$B$34 -> 3450 | E23: =E5*Inputs!$B$34 -> 4600
A24: Dive cover for everyone including George (short-term plan via the shop) | B24: =B3*Inputs!$B$35 -> 0 | C24: =C3*Inputs!$B$35 -> 0 | D24: =D3*Inputs!$B$35 -> 0 | E24: =E3*Inputs!$B$35 -> 0
A25: Hotel Plaza block, all rooms, less one comp room per 14 paid | B25: =(B7-INT(B7/(Inputs!$B$32+1)))*(Inputs!$B$27*Inputs!$B$29+Inputs!$B$28*Inputs!$B$30) -> 3444 | C25: =(C7-INT(C7/(Inputs!$B$32+1)))*(Inputs!$B$27*Inputs!$B$29+Inputs!$B$28*Inputs!$B$30) -> 4920 | D25: =(D7-INT(D7/(Inputs!$B$32+1)))*(Inputs!$B$27*Inputs!$B$29+Inputs!$B$28*Inputs!$B$30) -> 6888 | E25: =(E7-INT(E7/(Inputs!$B$32+1)))*(Inputs!$B$27*Inputs!$B$29+Inputs!$B$28*Inputs!$B$30) -> 9348
A26: George's flight allowance | B26: =Inputs!$B$38 -> 700 | C26: =Inputs!$B$38 -> 700 | D26: =Inputs!$B$38 -> 700 | E26: =Inputs!$B$38 -> 700
A27: TOTAL COSTS | B27: =B18+B19+B20+B21+B22+B23+B24+B25+B26 -> 16522 | C27: =C18+C19+C20+C21+C22+C23+C24+C25+C26 -> 23560 | D27: =D18+D19+D20+D21+D22+D23+D24+D25+D26 -> 34198 | E27: =E18+E19+E20+E21+E22+E23+E24+E25+E26 -> 45328
A28: Result
A29: Surplus (contingency and over-recovery; refunded pro rata or held) | B29: =B9-B27 -> 128 | C29: =C9-C27 -> 740 | D29: =D9-D27 -> 2852 | E29: =E9-E27 -> 4472
A30: Surplus per paying person | B30: =B29/B4 -> 9.8461538 | C30: =C29/C4 -> 38.947368 | D30: =D29/D4 -> 98.344828 | E30: =E29/E4 -> 114.66667
A31: Surplus as a share of revenue | B31: =B29/B9 -> 0.0076876877 | C31: =C29/C9 -> 0.030452675 | D31: =D29/D9 -> 0.076977058 | E31: =E29/E9 -> 0.089799197
A32: Covered? (surplus must stay positive at the minimum headcount) | B32: =IF(B29>=0,"yes","NO") -> yes | C32: =IF(C29>=0,"yes","NO") -> yes | D32: =IF(D29>=0,"yes","NO") -> yes | E32: =IF(E29>=0,"yes","NO") -> yes
A33: George's pot: commission (flight and room already carried above) | B33: =B19 -> 360 | C33: =C19 -> 540 | D33: =D19 -> 840 | E33: =E19 -> 1140
A34: Deposits and cash
A35: Participant deposits at sign-up (USD 400 each) | B35: =B4*400 -> 5200 | C35: =C4*400 -> 7600 | D35: =D4*400 -> 11600 | E35: =E4*400 -> 15600
A36: Blue Note 25% deposit + hotel deposit | B36: =B16*Inputs!$B$21+B25*Inputs!$B$31 -> 2881 | C36: =C16*Inputs!$B$21+C25*Inputs!$B$31 -> 4180 | D36: =D16*Inputs!$B$21+D25*Inputs!$B$31 -> 6072 | E36: =E16*Inputs!$B$21+E25*Inputs!$B$31 -> 8087
A37: Deposit cover (positive means deposits fund the outflow) | B37: =B35-B36 -> 2319 | C37: =C35-C36 -> 3420 | D37: =D35-D36 -> 5528 | E37: =E35-E36 -> 7513
A38: Balances due from participants by Fri 6 Nov | B38: =B9-B35 -> 11450 | C38: =C9-C35 -> 16700 | D38: =D9-D35 -> 25450 | E38: =E9-E35 -> 34200
A39: Blue Note balance Fri 13 Nov + rental + hotel balance + eLearning + DAN | B39: =B18-B16*Inputs!$B$21+B20+B25*(1-Inputs!$B$31)+B23+B24 -> 11853 | C39: =C18-C16*Inputs!$B$21+C20+C25*(1-Inputs!$B$31)+C23+C24 -> 17100 | D39: =D18-D16*Inputs!$B$21+D20+D25*(1-Inputs!$B$31)+D23+D24 -> 25026 | E39: =E18-E16*Inputs!$B$21+E20+E25*(1-Inputs!$B$31)+E23+E24 -> 33321
A40: Cash float to carry to the island (park fees) | B40: =B22 -> 728 | C40: =C22 -> 1040 | D40: =D22 -> 1560 | E40: =E22 -> 2080
...

Sheet Payments
A1: Payment schedule and refund policy (mirrors Blue Note's terms)
A2: date | B2: what | C2: who
A3: by Fri 2 Oct | B3: Sign-ups open on CampusGroups; deposit USD 400 per person holds a place | C3: participants
A4: Sat 10 Oct | B4: Sign-up deadline for the first block; headcount to Blue Note and Hotel Plaza | C4: George
A5: by Thu 15 Oct | B5: Blue Note deposit 25% of the gross invoice; hotel deposit (terms to confirm) | C5: club account
A6: Fri 6 Nov | B6: Participant balances due (fee less deposit, plus any add-ons) | C6: participants
A7: Fri 13 Nov | B7: Blue Note final payment (30 days out); hotel balance per its terms; buy eLearning codes | C7: club account
A8: Sun 6 Dec | B8: Blue Note's 7-day refund cut-off | C8: everyone
A9: Sun 13 Dec | B9: Arrival; park fees paid from the club float; meals, drinks, tips and transfers are each person's own | C9: George
A10: after the trip | B10: Unused contingency and any surplus refunded pro rata | C10: club account
A12: Refund ladder | B12: Deposit refundable in full until Fri 6 Nov; 7 Nov to 6 Dec refundable only if the place is resold or Blue Note refunds it; from 7 Dec no refund, only Blue Note credit where given. Weather cancellations: Blue Note reschedules or refunds the missed dives. | C12: policy
A13: Money handling | B13: All payments through CampusGroups or Blue Note's own link, never personal Venmo or Zelle. The sign-up page states that the leader's diving is comped by the shop, his flight and half-room are carried by the group, and the shop's commission goes to him. | C13: policy
