Workbook

Sheet Summary
A1: Summary — all-in price per person vs ceiling
A3: Prices before any organiser charge, at the airfare midpoint and 2 sharing. Organiser charge under Approach 2 shown separately. Every price rests on advertised or inferred figures; none is a quote.
A5: Cozumel, 6 nights (Sun 13 – Sat 19 Dec)
B6: Certified | C6: Beginner | D6: Advanced
A7: All-in per person | B7: =Cozumel!B22 -> 2201.3384 | C7: =Cozumel!C22 -> 2247.9617 | D7: =Cozumel!D22 -> 2894.3384
A8: Ceiling | B8: =Inputs!$B$15 -> 2000 | C8: =Inputs!$B$16 -> 2300 | D8: =Inputs!$B$15 -> 2000
A9: Headroom | B9: =B8-B7 -> -201.33836 | C9: =C8-C7 -> 52.038305 | D9: =D8-D7 -> -894.33836
A10: Organiser charge per head (Approach 2) at 20 / 30 / 40 | B10: =Cozumel!B65 -> 74.842105 | C10: =Cozumel!C65 -> 49.034483 | D10: =Cozumel!D65 -> 36.461538
A11: 5-night version, all-in per person | B11: =Cozumel!B46 -> 2078.3511 | C11: =Cozumel!C46 -> 2022.9745 | D11: =Cozumel!D46 -> 2771.3511
A12: Core only (excl. meals, tips, insurance), 6 nights | B12: =Cozumel!B23 -> 1822.3384 | C12: =Cozumel!C23 -> 1868.9617 | D12: =Cozumel!D23 -> 2515.3384
A14: Egypt, Marsa Shagra (Sat 2 – Sat 9 Jan)
B15: Certified | C15: Beginner | D15: Advanced
A16: All-in per person, Royal Tent, via Hurghada | B16: =January!B21 -> 2577.475 | C16: =January!C21 -> 2727.6665 | D16: =January!D21 -> 2962.699
A17: All-in per person, Deluxe Chalet, via Marsa Alam | B17: =January!B43 -> 2774.673 | C17: =January!C43 -> 2924.8645 | D17: =January!D43 -> 3159.897
A18: Ceiling | B18: =Inputs!$B$17 -> 2700 | C18: =Inputs!$B$17 -> 2700 | D18: =Inputs!$B$17 -> 2700
A19: Headroom (Royal Tent) | B19: =B18-B16 -> 122.525 | C19: =C18-C16 -> -27.6665 | D19: =D18-D16 -> -262.699
A20: Organiser charge per head (Approach 2) at 15 / 20 / 25 | B20: =January!B63 -> 110.64746 | C20: =January!C63 -> 81.529711 | D20: =January!D63 -> 64.544354
A21: Core only (excl. incidentals, tips, insurance), Royal Tent | B21: =January!B22 -> 2318.475 | C21: =January!C22 -> 2468.6665 | D21: =January!D22 -> 2703.699
A23: Thanksgiving (10 people)
B24: 25–29 Nov | C24: 19–24 Nov
A25: Puerto Rico, all-in per person | B25: =Thanksgiving!C18 -> 1720 | C25: =Thanksgiving!C35 -> 1988
A26: Tiger Beach, all-in per person | B26: =Thanksgiving!C51 -> 2366.8 | C26: =Thanksgiving!C69 -> 2980.7
A27: Ceiling | B27: =Inputs!$B$14 -> 1500 | C27: =Inputs!$B$14 -> 1500
A28: Puerto Rico headroom | B28: =B27-B25 -> -220 | C28: =C27-C25 -> -488
A29: Tiger Beach extra vs Puerto Rico | B29: =B26-B25 -> 646.8 | C29: =C26-C25 -> 992.7
A30: Puerto Rico core only (excl. meals, tips, insurance) | B30: =Thanksgiving!C19 -> 1411 | C30: =Thanksgiving!C36 -> 1644

Sheet Inputs
A1: Inputs — Wharton Outdoors Club dive trips 2026–27
A3: Blue cells are inputs; every other sheet reads from here. Flags: ADVERTISED (snippet) = seen on the named source; QUOTE NEEDED = unverified lead; INFERRED = our estimate. Sources are listed in pricing/sources.csv.
A5: Exchange rates (mid-market, 21 Sep 2026)
A6: USD per EUR 1 | B6: 1.1465 | C6: USD/EUR | D6: ADVERTISED (snippet)
A7: MXN per USD 1 | B7: 17.23 | C7: MXN/USD | D7: ADVERTISED (snippet)
A9: Group composition
A10: Beginner share of group (Cozumel, Egypt) | B10: 0.5 | C10: share | D10: brief
A11: Advanced share of group | B11: 0.15 | C11: share | D11: brief
A13: Budget ceilings (all-in incl. flights, per person)
A14: Thanksgiving | B14: 1500 | C14: USD | D14: brief
A15: Cozumel — certified | B15: 2000 | C15: USD | D15: brief
A16: Cozumel — beginner | B16: 2300 | C16: USD | D16: brief
A17: Egypt | B17: 2700 | C17: USD | D17: brief
A19: Shared allowances
A20: Dive-accident insurance (DAN membership + Preferred plan, annual) | B20: 119 | C20: USD | D20: ADVERTISED (snippet)
A21: Meals and incidentals per day where not on full board | B21: 35 | C21: USD/day | D21: INFERRED
A22: Tips and local extras per trip | B22: 50 | C22: USD | D22: INFERRED
A24: Cozumel, Sun 13 – Sat 19 Dec 2026 (6 nights, confirmed 22 Sep) and 5-night variant
A25: Flight PHL–CZM return, low | B25: 568 | C25: USD | D25: ADVERTISED (snippet, aggregator)
A26: Flight PHL–CZM return, high | B26: 800 | C26: USD | D26: ADVERTISED (snippet, aggregator)
A27: Alternative: PHL–CUN + ADO bus + ferry, all-in return | B27: 400 | C27: USD | D27: ADVERTISED (snippet); mid of 315–450
A28: CZM airport shared van, each way | B28: 15 | C28: USD | D28: ADVERTISED (snippet)
A29: Hotel Cozumel & Resort, pp/night, 2 sharing, breakfast incl. | B29: 54 | C29: USD | D29: ADVERTISED (snippet); upper of 41–54
A30: Hotel Cozumel & Resort, pp/night, 3 sharing | B30: 40 | C30: USD | D30: INFERRED (30–40)
A31: Casa Mexicana, pp/night, 2 sharing, breakfast incl. | B31: 84 | C31: USD | D31: ADVERTISED (snippet); upper of 65–84
A32: Nights, 6-night version (Sun 13 – Sat 19) | B32: 6 | C32: nights | D32: dates confirmed 22 Sep
A33: Nights, 5-night version | B33: 5 | C33: nights | D33: brief
A34: PADI Open Water in-water course, gear, wetsuit and DAN training cover incl. (Sand Dollar) | B34: 350 | C34: USD | D34: QUOTED 2026-09-22 (Sand Dollar email); Blue Note advertised 400
A35: PADI Open Water eLearning, bought from PADI | B35: 195 | C35: USD | D35: ADVERTISED (snippet); 195–230
A36: 5-day / 10-dive package (Blue Note), MXN price | B36: 10500 | C36: MXN | D36: ADVERTISED (snippet); USD 600 listed
... A50: Operator free places: one per N paying (diving only) | B50: 10 | C50: paying | D50: QUOTED 2026-09-22: Aldora 1 comp at 10+ paid; Sand Dollar one free diver
A52: Egypt (Marsa Shagra), Sat 2 – Sat 9 Jan 2027, 6 nights on the ground
A53: Flight PHL–HRG return via Lufthansa Group hub, low | B53: 700 | C53: USD | D53: ADVERTISED (snippet, aggregator)
A54: Flight PHL–HRG return, high | B54: 1300 | C54: USD | D54: ADVERTISED (snippet, aggregator)
A55: Flight PHL–RMF return (thin January schedule) | B55: 1300 | C55: USD | D55: INFERRED; 1,000–1,600
A56: Open-jaw add-on: HRG–ZRH one-way instead of return leg (net of return leg) | B56: 0 | C56: USD | D56: QUOTE NEEDED; one-way ~USD 550 seen
A57: Nights on the ground (Sun 3 – Sat 9) | B57: 6 | C57: nights | D57: itinerary
A58: Royal Tent, full board, pp/night sharing | B58: 78 | C58: EUR | D58: QUOTE NEEDED (brief; low season)
A59: Deluxe Chalet, full board, pp/night sharing | B59: 113 | C59: EUR | D59: QUOTE NEEDED (brief; low season)
A60: PADI Open Water incl. gear | B60: 358 | C60: EUR | D60: QUOTE NEEDED (brief)
...

Sheet Cozumel
A1: Cozumel — Sun 13 – Sat 19 Dec 2026 (6 nights, confirmed 22 Sep) and 5-night variant
A3: All figures per person, USD. Reads from Inputs. Lodging at Hotel Cozumel & Resort, 2 sharing, breakfast included. Flights at the midpoint of the aggregator band.
A5: A. Per-person cost, 6-night version (no spare day: a norther on Sat/Sun hits the certification dives)
A6: Item | B6: Certified | C6: Beginner | D6: Advanced
A7: Flight PHL–CZM return (band midpoint) | B7: =AVERAGE(Inputs!$B$25,Inputs!$B$26) -> 684 | C7: =AVERAGE(Inputs!$B$25,Inputs!$B$26) -> 684 | D7: =AVERAGE(Inputs!$B$25,Inputs!$B$26) -> 684
A8: Airport transfers | B8: =2*Inputs!$B$28 -> 30 | C8: =2*Inputs!$B$28 -> 30 | D8: =2*Inputs!$B$28 -> 30
A9: Lodging, 2 sharing, breakfast included | B9: =Inputs!$B$32*Inputs!$B$29 -> 324 | C9: =Inputs!$B$32*Inputs!$B$29 -> 324 | D9: =Inputs!$B$32*Inputs!$B$29 -> 324
A10: Open Water in-water course (gear included) | B10: 0 | C10: =Inputs!$B$34 -> 350 | D10: 0
A11: PADI eLearning | B11: 0 | C11: =Inputs!$B$35 -> 195 | D11: 0
A12: Boat diving (package for certified; fun days for beginners) | B12: =Inputs!$B$36/Inputs!$B$7 -> 609.40221 | C12: =Inputs!$B$47*Inputs!$B$37 -> 204 | D12: =Inputs!$B$36/Inputs!$B$7 -> 609.40221
A13: Advanced Open Water course | B13: 0 | C13: 0 | D13: =Inputs!$B$41 -> 530
A14: Marine park fee | B14: =Inputs!$B$45*Inputs!$B$38/Inputs!$B$7 -> 69.936158 | C14: =(Inputs!$B$49+Inputs!$B$47)*Inputs!$B$38/Inputs!$B$7 -> 41.961695 | D14: =Inputs!$B$45*Inputs!$B$38/Inputs!$B$7 -> 69.936158
A15: Gear rental | B15: =Inputs!$B$45*Inputs!$B$39 -> 100 | C15: =Inputs!$B$47*Inputs!$B$39 -> 40 | D15: =Inputs!$B$45*Inputs!$B$39 -> 100
A16: Refresher (if >12 months since last dive) | B16: =Inputs!$B$40 -> 5 | C16: 0 | D16: =Inputs!$B$40 -> 5
A17: Nitrox fills (advanced, 6 tanks) | B17: 0 | C17: 0 | D17: =6*Inputs!$B$42 -> 78
A18: Night dive (advanced) | B18: 0 | C18: 0 | D18: =Inputs!$B$43 -> 85
A19: Meals and incidentals | B19: =Inputs!$B$32*Inputs!$B$21 -> 210 | C19: =Inputs!$B$32*Inputs!$B$21 -> 210 | D19: =Inputs!$B$32*Inputs!$B$21 -> 210
A20: Tips and local extras | B20: =Inputs!$B$22 -> 50 | C20: =Inputs!$B$22 -> 50 | D20: =Inputs!$B$22 -> 50
A21: Dive-accident insurance | B21: =Inputs!$B$20 -> 119 | C21: =Inputs!$B$20 -> 119 | D21: =Inputs!$B$20 -> 119
A22: Total per person | B22: =SUM(B7:B21) -> 2201.3384 | C22: =SUM(C7:C21) -> 2247.9617 | D22: =SUM(D7:D21) -> 2894.3384
A23: of which core: flights, transfers, lodging, diving, fees (excl. meals, tips, insurance) | B23: =B22-SUM(B19:B21) -> 1822.3384 | C23: =C22-SUM(C19:C21) -> 1868.9617 | D23: =D22-SUM(D19:D21) -> 2515.3384
A24: Budget ceiling | B24: =Inputs!$B$15 -> 2000 | C24: =Inputs!$B$16 -> 2300 | D24: =Inputs!$B$15 -> 2000
A25: Headroom (negative = over ceiling) | B25: =B24-B22 -> -201.33836 | C25: =C24-C22 -> 52.038305 | D25: =D24-D22 -> -894.33836
A26: Optional bull-shark day, Playa del Carmen (BAITED), not in total | B26: =Inputs!$B$44 -> 260 | C26: =Inputs!$B$44 -> 260 | D26: =Inputs!$B$44 -> 260
A29: B. Per-person cost, 5-night version (Sun 13 return; no norther buffer)
A30: Item | B30: Certified | C30: Beginner | D30: Advanced
A31: Flight PHL–CZM return (band midpoint) | B31: =AVERAGE(Inputs!$B$25,Inputs!$B$26) -> 684 | C31: =AVERAGE(Inputs!$B$25,Inputs!$B$26) -> 684 | D31: =AVERAGE(Inputs!$B$25,Inputs!$B$26) -> 684
A32: Airport transfers | B32: =2*Inputs!$B$28 -> 30 | C32: =2*Inputs!$B$28 -> 30 | D32: =2*Inputs!$B$28 -> 30
A33: Lodging, 2 sharing, breakfast included | B33: =Inputs!$B$33*Inputs!$B$29 -> 270 | C33: =Inputs!$B$33*Inputs!$B$29 -> 270 | D33: =Inputs!$B$33*Inputs!$B$29 -> 270
A34: Open Water in-water course (gear included) | B34: 0 | C34: =Inputs!$B$34 -> 350 | D34: 0
A35: PADI eLearning | B35: 0 | C35: =Inputs!$B$35 -> 195 | D35: 0
A36: Boat diving (package for certified; fun days for beginners) | B36: =Inputs!$B$36/Inputs!$B$7 -> 609.40221 | C36: =Inputs!$B$48*Inputs!$B$37 -> 102 | D36: =Inputs!$B$36/Inputs!$B$7 -> 609.40221
A37: Advanced Open Water course | B37: 0 | C37: 0 | D37: =Inputs!$B$41 -> 530
A38: Marine park fee | B38: =Inputs!$B$46*Inputs!$B$38/Inputs!$B$7 -> 55.948926 | C38: =(Inputs!$B$49+Inputs!$B$48)*Inputs!$B$38/Inputs!$B$7 -> 27.974463 | D38: =Inputs!$B$46*Inputs!$B$38/Inputs!$B$7 -> 55.948926
A39: Gear rental | B39: =Inputs!$B$46*Inputs!$B$39 -> 80 | C39: =Inputs!$B$48*Inputs!$B$39 -> 20 | D39: =Inputs!$B$46*Inputs!$B$39 -> 80
A40: Refresher (if >12 months since last dive) | B40: =Inputs!$B$40 -> 5 | C40: 0 | D40: =Inputs!$B$40 -> 5
A41: Nitrox fills (advanced, 6 tanks) | B41: 0 | C41: 0 | D41: =6*Inputs!$B$42 -> 78
A42: Night dive (advanced) | B42: 0 | C42: 0 | D42: =Inputs!$B$43 -> 85
A43: Meals and incidentals | B43: =Inputs!$B$33*Inputs!$B$21 -> 175 | C43: =Inputs!$B$33*Inputs!$B$21 -> 175 | D43: =Inputs!$B$33*Inputs!$B$21 -> 175
A44: Tips and local extras | B44: =Inputs!$B$22 -> 50 | C44: =Inputs!$B$22 -> 50 | D44: =Inputs!$B$22 -> 50
...

Sheet January
A1: Egypt, Marsa Shagra — Sat 2 – Sat 9 Jan 2027 (6 nights on the ground)
A3: All figures per person, USD, converted from EUR at the Inputs rate. Full board included in lodging. Flights PHL–HRG via a Lufthansa Group hub at the band midpoint; transfers from Hurghada (3 h) unless RMF proves bookable.
A5: A. Per-person cost, Royal Tent, transfers from Hurghada (10–20 people)
A6: Item | B6: Certified | C6: Beginner | D6: Advanced
A7: Flight PHL–HRG return via Europe (band midpoint) | B7: =AVERAGE(Inputs!$B$53,Inputs!$B$54) -> 1000 | C7: =AVERAGE(Inputs!$B$53,Inputs!$B$54) -> 1000 | D7: =AVERAGE(Inputs!$B$53,Inputs!$B$54) -> 1000
A8: Airport transfers, both ways | B8: =2*Inputs!$B$71*Inputs!$B$6 -> 94.013 | C8: =2*Inputs!$B$71*Inputs!$B$6 -> 94.013 | D8: =2*Inputs!$B$71*Inputs!$B$6 -> 94.013
A9: Lodging, full board, 2 sharing | B9: =Inputs!$B$57*Inputs!$B$58*Inputs!$B$6 -> 536.562 | C9: =Inputs!$B$57*Inputs!$B$58*Inputs!$B$6 -> 536.562 | D9: =Inputs!$B$57*Inputs!$B$58*Inputs!$B$6 -> 536.562
A10: Open Water course incl. gear | B10: 0 | C10: =Inputs!$B$60*Inputs!$B$6 -> 410.447 | D10: 0
A11: PADI e-code | B11: 0 | C11: =Inputs!$B$61*Inputs!$B$6 -> 107.771 | D11: 0
A12: House-reef dive package (5 days) or post-course dive days | B12: =Inputs!$B$62*Inputs!$B$6 -> 397.8355 | C12: =Inputs!$B$76*Inputs!$B$63*Inputs!$B$6 -> 158.217 | D12: =Inputs!$B$62*Inputs!$B$6 -> 397.8355
A13: Advanced Open Water course | B13: 0 | C13: 0 | D13: =Inputs!$B$65*Inputs!$B$6 -> 361.1475
A14: Gear rental | B14: =Inputs!$B$75*Inputs!$B$64*Inputs!$B$6 -> 85.9875 | C14: =Inputs!$B$76*Inputs!$B$64*Inputs!$B$6 -> 34.395 | D14: =Inputs!$B$75*Inputs!$B$64*Inputs!$B$6 -> 85.9875
A15: Excursions: Dolphin House and Abu Dabab (certified); Elphinstone (advanced) | B15: =(Inputs!$B$66+Inputs!$B$67)*Inputs!$B$6 -> 144.459 | C15: =Inputs!$B$67*Inputs!$B$6 -> 67.6435 | D15: =(Inputs!$B$66+Inputs!$B$68)*Inputs!$B$6 -> 168.5355
A16: Visa and meet-and-assist | B16: =Inputs!$B$72*Inputs!$B$6 -> 51.5925 | C16: =Inputs!$B$72*Inputs!$B$6 -> 51.5925 | D16: =Inputs!$B$72*Inputs!$B$6 -> 51.5925
A17: On-site chamber fee | B17: =Inputs!$B$73*Inputs!$B$6 -> 8.0255 | C17: =Inputs!$B$73*Inputs!$B$6 -> 8.0255 | D17: =Inputs!$B$73*Inputs!$B$6 -> 8.0255
A18: Incidentals on full board | B18: =Inputs!$B$57*Inputs!$B$74 -> 90 | C18: =Inputs!$B$57*Inputs!$B$74 -> 90 | D18: =Inputs!$B$57*Inputs!$B$74 -> 90
A19: Tips and local extras | B19: =Inputs!$B$22 -> 50 | C19: =Inputs!$B$22 -> 50 | D19: =Inputs!$B$22 -> 50
A20: Dive-accident insurance | B20: =Inputs!$B$20 -> 119 | C20: =Inputs!$B$20 -> 119 | D20: =Inputs!$B$20 -> 119
A21: Total per person | B21: =SUM(B7:B20) -> 2577.475 | C21: =SUM(C7:C20) -> 2727.6665 | D21: =SUM(D7:D20) -> 2962.699
A22: of which core: flights, transfers, lodging, diving, fees (excl. meals, tips, insurance) | B22: =B21-SUM(B18:B20) -> 2318.475 | C22: =C21-SUM(C18:C20) -> 2468.6665 | D22: =D21-SUM(D18:D20) -> 2703.699
A23: Budget ceiling | B23: =Inputs!$B$17 -> 2700 | C23: =Inputs!$B$17 -> 2700 | D23: =Inputs!$B$17 -> 2700
A24: Headroom (negative = over ceiling) | B24: =B23-B21 -> 122.525 | C24: =C23-C21 -> -27.6665 | D24: =D23-D21 -> -262.699
A27: B. Per-person cost, Deluxe Chalet, transfers from Marsa Alam airport (10–20 people)
A28: Item | B28: Certified | C28: Beginner | D28: Advanced
A29: Flight PHL–HRG return via Europe (band midpoint) | B29: =AVERAGE(Inputs!$B$53,Inputs!$B$54) -> 1000 | C29: =AVERAGE(Inputs!$B$53,Inputs!$B$54) -> 1000 | D29: =AVERAGE(Inputs!$B$53,Inputs!$B$54) -> 1000
A30: Airport transfers, both ways | B30: =2*Inputs!$B$69*Inputs!$B$6 -> 50.446 | C30: =2*Inputs!$B$69*Inputs!$B$6 -> 50.446 | D30: =2*Inputs!$B$69*Inputs!$B$6 -> 50.446
A31: Lodging, full board, 2 sharing | B31: =Inputs!$B$57*Inputs!$B$59*Inputs!$B$6 -> 777.327 | C31: =Inputs!$B$57*Inputs!$B$59*Inputs!$B$6 -> 777.327 | D31: =Inputs!$B$57*Inputs!$B$59*Inputs!$B$6 -> 777.327
A32: Open Water course incl. gear | B32: 0 | C32: =Inputs!$B$60*Inputs!$B$6 -> 410.447 | D32: 0
A33: PADI e-code | B33: 0 | C33: =Inputs!$B$61*Inputs!$B$6 -> 107.771 | D33: 0
A34: House-reef dive package (5 days) or post-course dive days | B34: =Inputs!$B$62*Inputs!$B$6 -> 397.8355 | C34: =Inputs!$B$76*Inputs!$B$63*Inputs!$B$6 -> 158.217 | D34: =Inputs!$B$62*Inputs!$B$6 -> 397.8355
A35: Advanced Open Water course | B35: 0 | C35: 0 | D35: =Inputs!$B$65*Inputs!$B$6 -> 361.1475
A36: Gear rental | B36: =Inputs!$B$75*Inputs!$B$64*Inputs!$B$6 -> 85.9875 | C36: =Inputs!$B$76*Inputs!$B$64*Inputs!$B$6 -> 34.395 | D36: =Inputs!$B$75*Inputs!$B$64*Inputs!$B$6 -> 85.9875
A37: Excursions: Dolphin House and Abu Dabab (certified); Elphinstone (advanced) | B37: =(Inputs!$B$66+Inputs!$B$67)*Inputs!$B$6 -> 144.459 | C37: =Inputs!$B$67*Inputs!$B$6 -> 67.6435 | D37: =(Inputs!$B$66+Inputs!$B$68)*Inputs!$B$6 -> 168.5355
A38: Visa and meet-and-assist | B38: =Inputs!$B$72*Inputs!$B$6 -> 51.5925 | C38: =Inputs!$B$72*Inputs!$B$6 -> 51.5925 | D38: =Inputs!$B$72*Inputs!$B$6 -> 51.5925
A39: On-site chamber fee | B39: =Inputs!$B$73*Inputs!$B$6 -> 8.0255 | C39: =Inputs!$B$73*Inputs!$B$6 -> 8.0255 | D39: =Inputs!$B$73*Inputs!$B$6 -> 8.0255
A40: Incidentals on full board | B40: =Inputs!$B$57*Inputs!$B$74 -> 90 | C40: =Inputs!$B$57*Inputs!$B$74 -> 90 | D40: =Inputs!$B$57*Inputs!$B$74 -> 90
A41: Tips and local extras | B41: =Inputs!$B$22 -> 50 | C41: =Inputs!$B$22 -> 50 | D41: =Inputs!$B$22 -> 50
A42: Dive-accident insurance | B42: =Inputs!$B$20 -> 119 | C42: =Inputs!$B$20 -> 119 | D42: =Inputs!$B$20 -> 119
A43: Total per person | B43: =SUM(B29:B42) -> 2774.673 | C43: =SUM(C29:C42) -> 2924.8645 | D43: =SUM(D29:D42) -> 3159.897
A44: of which core: flights, transfers, lodging, diving, fees (excl. meals, tips, insurance) | B44: =B43-SUM(B40:B42) -> 2515.673 | C44: =C43-SUM(C40:C42) -> 2665.8645 | D44: =D43-SUM(D40:D42) -> 2900.897
...

Sheet Thanksgiving
A1: Thanksgiving — Puerto Rico (La Parguera) and Tiger Beach (Grand Bahama), 10 certified divers
A3: All figures per person, USD, 2 sharing, own dive gear. Car cost per head depends on group size (people per car on Inputs). Tiger Beach dives are BAITED shark dives; sales are final with a one-year weather credit.
A5: Group size incl. George | B5: 8 | C5: 10 | D5: 12
A7: A. Puerto Rico, Wed 25 – Sun 29 Nov (4 nights, 3 dive days)
A8: Item | B8: 8 people | C8: 10 people | D8: 12 people
A9: Flight PHL–SJU return nonstop (band midpoint) | B9: =AVERAGE(Inputs!$B$81,Inputs!$B$82) -> 550 | C9: =AVERAGE(Inputs!$B$81,Inputs!$B$82) -> 550 | D9: =AVERAGE(Inputs!$B$81,Inputs!$B$82) -> 550
A10: Car hire, fuel and tolls (shared) | B10: =(ROUNDUP(B5/Inputs!$B$94,0)*(Inputs!$B$83*Inputs!$B$93+Inputs!$B$95))/B5 -> 85 | C10: =(ROUNDUP(C5/Inputs!$B$94,0)*(Inputs!$B$83*Inputs!$B$93+Inputs!$B$95))/C5 -> 102 | D10: =(ROUNDUP(D5/Inputs!$B$94,0)*(Inputs!$B$83*Inputs!$B$93+Inputs!$B$95))/D5 -> 85
A11: Lodging, 2 sharing | B11: =Inputs!$B$83*Inputs!$B$85 -> 300 | C11: =Inputs!$B$83*Inputs!$B$85 -> 300 | D11: =Inputs!$B$83*Inputs!$B$85 -> 300
A12: Wall dives (two-tank days less Desecheo days) | B12: =(Inputs!$B$89-Inputs!$B$91)*Inputs!$B$87 -> 274 | C12: =(Inputs!$B$89-Inputs!$B$91)*Inputs!$B$87 -> 274 | D12: =(Inputs!$B$89-Inputs!$B$91)*Inputs!$B$87 -> 274
A13: Desecheo day incl. park fee (weather permitting) | B13: =Inputs!$B$91*Inputs!$B$88 -> 140 | C13: =Inputs!$B$91*Inputs!$B$88 -> 140 | D13: =Inputs!$B$91*Inputs!$B$88 -> 140
A14: Bio bay evening | B14: =Inputs!$B$92 -> 45 | C14: =Inputs!$B$92 -> 45 | D14: =Inputs!$B$92 -> 45
A15: Meals and incidentals | B15: =Inputs!$B$83*Inputs!$B$21 -> 140 | C15: =Inputs!$B$83*Inputs!$B$21 -> 140 | D15: =Inputs!$B$83*Inputs!$B$21 -> 140
A16: Tips and local extras | B16: =Inputs!$B$22 -> 50 | C16: =Inputs!$B$22 -> 50 | D16: =Inputs!$B$22 -> 50
A17: Dive-accident insurance | B17: =Inputs!$B$20 -> 119 | C17: =Inputs!$B$20 -> 119 | D17: =Inputs!$B$20 -> 119
A18: Total per person | B18: =SUM(B9:B17) -> 1703 | C18: =SUM(C9:C17) -> 1720 | D18: =SUM(D9:D17) -> 1703
A19: of which core: flights, transfers, lodging, diving, fees (excl. meals, tips, insurance) | B19: =B18-SUM(B15:B17) -> 1394 | C19: =C18-SUM(C15:C17) -> 1411 | D19: =D18-SUM(D15:D17) -> 1394
A20: Budget ceiling | B20: =Inputs!$B$14 -> 1500 | C20: =Inputs!$B$14 -> 1500 | D20: =Inputs!$B$14 -> 1500
A21: Headroom (negative = over ceiling) | B21: =B20-B18 -> -203 | C21: =C20-C18 -> -220 | D21: =D20-D18 -> -203
A24: B. Puerto Rico, Thu 19 – Tue 24 Nov (5 nights, 4 dive days; four class days missed; Colombia trek clash)
A25: Item | B25: 8 people | C25: 10 people | D25: 12 people
A26: Flight PHL–SJU return nonstop (band midpoint) | B26: =AVERAGE(Inputs!$B$81,Inputs!$B$82) -> 550 | C26: =AVERAGE(Inputs!$B$81,Inputs!$B$82) -> 550 | D26: =AVERAGE(Inputs!$B$81,Inputs!$B$82) -> 550
A27: Car hire, fuel and tolls (shared) | B27: =(ROUNDUP(B5/Inputs!$B$94,0)*(Inputs!$B$84*Inputs!$B$93+Inputs!$B$95))/B5 -> 102.5 | C27: =(ROUNDUP(C5/Inputs!$B$94,0)*(Inputs!$B$84*Inputs!$B$93+Inputs!$B$95))/C5 -> 123 | D27: =(ROUNDUP(D5/Inputs!$B$94,0)*(Inputs!$B$84*Inputs!$B$93+Inputs!$B$95))/D5 -> 102.5
A28: Lodging, 2 sharing | B28: =Inputs!$B$84*Inputs!$B$85 -> 375 | C28: =Inputs!$B$84*Inputs!$B$85 -> 375 | D28: =Inputs!$B$84*Inputs!$B$85 -> 375
A29: Wall dives (two-tank days less Desecheo days) | B29: =(Inputs!$B$90-Inputs!$B$91)*Inputs!$B$87 -> 411 | C29: =(Inputs!$B$90-Inputs!$B$91)*Inputs!$B$87 -> 411 | D29: =(Inputs!$B$90-Inputs!$B$91)*Inputs!$B$87 -> 411
A30: Desecheo day incl. park fee (weather permitting) | B30: =Inputs!$B$91*Inputs!$B$88 -> 140 | C30: =Inputs!$B$91*Inputs!$B$88 -> 140 | D30: =Inputs!$B$91*Inputs!$B$88 -> 140
A31: Bio bay evening | B31: =Inputs!$B$92 -> 45 | C31: =Inputs!$B$92 -> 45 | D31: =Inputs!$B$92 -> 45
A32: Meals and incidentals | B32: =Inputs!$B$84*Inputs!$B$21 -> 175 | C32: =Inputs!$B$84*Inputs!$B$21 -> 175 | D32: =Inputs!$B$84*Inputs!$B$21 -> 175
A33: Tips and local extras | B33: =Inputs!$B$22 -> 50 | C33: =Inputs!$B$22 -> 50 | D33: =Inputs!$B$22 -> 50
A34: Dive-accident insurance | B34: =Inputs!$B$20 -> 119 | C34: =Inputs!$B$20 -> 119 | D34: =Inputs!$B$20 -> 119
A35: Total per person | B35: =SUM(B26:B34) -> 1967.5 | C35: =SUM(C26:C34) -> 1988 | D35: =SUM(D26:D34) -> 1967.5
A36: of which core: flights, transfers, lodging, diving, fees (excl. meals, tips, insurance) | B36: =B35-SUM(B32:B34) -> 1623.5 | C36: =C35-SUM(C32:C34) -> 1644 | D36: =D35-SUM(D32:D34) -> 1623.5
A37: Budget ceiling | B37: =Inputs!$B$14 -> 1500 | C37: =Inputs!$B$14 -> 1500 | D37: =Inputs!$B$14 -> 1500
A38: Headroom (negative = over ceiling) | B38: =B37-B35 -> -467.5 | C38: =C37-C35 -> -488 | D38: =D37-D35 -> -467.5
A41: C. Tiger Beach variant, Wed 25 – Sun 29 Nov (4 nights, 2 shark days + weather buffer)
A42: Item | B42: 8 people | C42: 10 people | D42: 12 people
A43: Flights PHL–FLL and FLL–FPO return | B43: =Inputs!$B$100+Inputs!$B$101 -> 600 | C43: =Inputs!$B$100+Inputs!$B$101 -> 600 | D43: =Inputs!$B$100+Inputs!$B$101 -> 600
A44: Airport – West End transfers | B44: =Inputs!$B$105 -> 50 | C44: =Inputs!$B$105 -> 50 | D44: =Inputs!$B$105 -> 50
A45: Lodging Old Bahama Bay, 2 sharing | B45: =Inputs!$B$83*Inputs!$B$103 -> 500 | C45: =Inputs!$B$83*Inputs!$B$103 -> 500 | D45: =Inputs!$B$83*Inputs!$B$103 -> 500
A46: Shark days (BAITED), incl. VAT | B46: =Inputs!$B$98*Inputs!$B$96*(1+Inputs!$B$97) -> 877.8 | C46: =Inputs!$B$98*Inputs!$B$96*(1+Inputs!$B$97) -> 877.8 | D46: =Inputs!$B$98*Inputs!$B$96*(1+Inputs!$B$97) -> 877.8
A47: Wetsuit rental if needed | B47: =Inputs!$B$98*Inputs!$B$106 -> 30 | C47: =Inputs!$B$98*Inputs!$B$106 -> 30 | D47: =Inputs!$B$98*Inputs!$B$106 -> 30
...
